INFO - 2023-06-20-20-56-41 - admin : (ERR000) Function started.
------------------------------------------------------------------------------------------------------------------------
ERROR - 2023-06-20-20-56-41 - admin : (ERR002) An exception occurred.
------------------------------------------------------------------------------------------------------------------------
Traceback (most recent call last):
  File "/home/reyhane/PythonProjects/Logger/./dorsa_logger.py", line 539, in wrapper
    fun(*args, **kwargs)
  File "/home/reyhane/PythonProjects/Logger/Examples/example3.py", line 26, in test
    raise Exception('This is a fake exception')
Exception: This is a fake exception
INFO - 2023-06-20-20-56-41 - admin : (ERR001) Function finished.
------------------------------------------------------------------------------------------------------------------------
