INFO - 2023-06-20-21-17-37 - admin : (ERR000) Function started.
------------------------------------------------------------------------------------------------------------------------
ERROR - 2023-06-20-21-17-37 - admin : (ERR002) An exception occurred.
------------------------------------------------------------------------------------------------------------------------
Traceback (most recent call last):
  File "/home/reyhane/PythonProjects/Logger/./dorsa_logger.py", line 550, in wrapper
    result = func(*args, **kwargs)
  File "/home/reyhane/PythonProjects/Logger/Examples/example3.py", line 26, in test
    raise Exception('This is a fake exception')
Exception: This is a fake exception
INFO - 2023-06-20-21-17-37 - admin : (ERR001) Function finished.
------------------------------------------------------------------------------------------------------------------------
