INFO - 2023-06-20-23-53-15 - admin : Function test started
------------------------------------------------------------------------------------------------------------------------
ERROR - 2023-06-20-23-53-15 - admin : Function test exception
------------------------------------------------------------------------------------------------------------------------
Traceback (most recent call last):
  File "/home/reyhane/PythonProjects/Logger/./dorsa_logger.py", line 561, in wrapper
    result = func(*args, **kwargs)
  File "/home/reyhane/PythonProjects/Logger/./dorsa_logger.py", line 587, in wrapper
    result = func(*args, **kwargs)
  File "/home/reyhane/PythonProjects/Logger/Examples/example3.py", line 26, in test
    raise Exception('This is a fake exception')
Exception: This is a fake exception
