INFO - 2023-06-20-23-26-17 - admin : Function started
------------------------------------------------------------------------------------------------------------------------
ERROR - 2023-06-20-23-26-17 - admin : Function exception
------------------------------------------------------------------------------------------------------------------------
Traceback (most recent call last):
  File "/home/reyhane/PythonProjects/Logger/./dorsa_logger.py", line 554, in wrapper
    result = func(*args, **kwargs)
  File "/home/reyhane/PythonProjects/Logger/Examples/example3.py", line 26, in test
    raise Exception('This is a fake exception')
Exception: This is a fake exception
INFO - 2023-06-20-23-26-17 - admin : Function ended
------------------------------------------------------------------------------------------------------------------------
